2025-09-22 20:55:26,889 - ERROR - root - firebase_admin_auth - initialize_firebase - 19 - Failed to initialize Firebase Admin SDK: [Errno 2] No such file or directory: '/rag-chat-api-key.json'
Traceback (most recent call last):
  File "D:\Repositories\GEN AI\rag\firebase_admin_auth.py", line 13, in initialize_firebase
    cred = credentials.Certificate(config.FIREBASE_SERVICE_ACCOUNT_KEY_PATH)
  File "D:\Repositories\GEN AI\rag\venv\Lib\site-packages\firebase_admin\credentials.py", line 97, in __init__
    with open(cert, encoding='utf-8') as json_file:
         ~~~~^^^^^^^^^^^^^^^^^^^^^^^^
FileNotFoundError: [Errno 2] No such file or directory: '/rag-chat-api-key.json'
2025-09-22 20:56:02,983 - ERROR - root - firebase_admin_auth - initialize_firebase - 19 - Failed to initialize Firebase Admin SDK: [Errno 2] No such file or directory: '/rag-chat-api-key.json'
Traceback (most recent call last):
  File "D:\Repositories\GEN AI\rag\firebase_admin_auth.py", line 13, in initialize_firebase
    cred = credentials.Certificate(config.FIREBASE_SERVICE_ACCOUNT_KEY_PATH)
  File "D:\Repositories\GEN AI\rag\venv\Lib\site-packages\firebase_admin\credentials.py", line 97, in __init__
    with open(cert, encoding='utf-8') as json_file:
         ~~~~^^^^^^^^^^^^^^^^^^^^^^^^
FileNotFoundError: [Errno 2] No such file or directory: '/rag-chat-api-key.json'
2025-09-22 20:56:13,312 - ERROR - root - firebase_admin_auth - initialize_firebase - 19 - Failed to initialize Firebase Admin SDK: [Errno 2] No such file or directory: '/rag-chat-api-key.json'
Traceback (most recent call last):
  File "D:\Repositories\GEN AI\rag\firebase_admin_auth.py", line 13, in initialize_firebase
    cred = credentials.Certificate(config.FIREBASE_SERVICE_ACCOUNT_KEY_PATH)
  File "D:\Repositories\GEN AI\rag\venv\Lib\site-packages\firebase_admin\credentials.py", line 97, in __init__
    with open(cert, encoding='utf-8') as json_file:
         ~~~~^^^^^^^^^^^^^^^^^^^^^^^^
FileNotFoundError: [Errno 2] No such file or directory: '/rag-chat-api-key.json'
2025-09-22 20:56:16,262 - ERROR - root - firebase_admin_auth - initialize_firebase - 19 - Failed to initialize Firebase Admin SDK: name 'firebase_admin' is not defined
Traceback (most recent call last):
  File "D:\Repositories\GEN AI\rag\firebase_admin_auth.py", line 14, in initialize_firebase
    firebase_admin.initialize_app(cred, {
    ^^^^^^^^^^^^^^
NameError: name 'firebase_admin' is not defined
2025-09-22 20:56:53,231 - ERROR - root - firebase_admin_auth - initialize_firebase - 20 - Failed to initialize Firebase Admin SDK: name 'firebase_admin' is not defined
Traceback (most recent call last):
  File "D:\Repositories\GEN AI\rag\firebase_admin_auth.py", line 15, in initialize_firebase
    firebase_admin.initialize_app(cred, {
    ^^^^^^^^^^^^^^
NameError: name 'firebase_admin' is not defined
2025-09-22 20:56:57,542 - ERROR - root - firebase_admin_auth - initialize_firebase - 19 - Failed to initialize Firebase Admin SDK: name 'firebase_admin' is not defined
Traceback (most recent call last):
  File "D:\Repositories\GEN AI\rag\firebase_admin_auth.py", line 14, in initialize_firebase
    firebase_admin.initialize_app(cred, {
    ^^^^^^^^^^^^^^
NameError: name 'firebase_admin' is not defined
2025-09-22 20:57:16,370 - ERROR - root - firebase_admin_auth - initialize_firebase - 20 - Failed to initialize Firebase Admin SDK: name 'firebase_admin' is not defined
Traceback (most recent call last):
  File "D:\Repositories\GEN AI\rag\firebase_admin_auth.py", line 15, in initialize_firebase
    firebase_admin.initialize_app(cred, {
    ^^^^^^^^^^^^^^
NameError: name 'firebase_admin' is not defined
2025-09-22 20:59:01,014 - ERROR - root - firebase_admin_auth - login_with_email_and_password - 108 - Failed to login user: {
  "error": {
    "code": 400,
    "message": "API key not valid. Please pass a valid API key.",
    "errors": [
      {
        "message": "API key not valid. Please pass a valid API key.",
        "domain": "global",
        "reason": "badRequest"
      }
    ],
    "status": "INVALID_ARGUMENT",
    "details": [
      {
        "@type": "type.googleapis.com/google.rpc.ErrorInfo",
        "reason": "API_KEY_INVALID",
        "domain": "googleapis.com",
        "metadata": {
          "service": "identitytoolkit.googleapis.com"
        }
      },
      {
        "@type": "type.googleapis.com/google.rpc.LocalizedMessage",
        "locale": "en-US",
        "message": "API key not valid. Please pass a valid API key."
      }
    ]
  }
}
Traceback (most recent call last):
  File "D:\Repositories\GEN AI\rag\firebase_admin_auth.py", line 101, in login_with_email_and_password
    response.raise_for_status()  # Raise an exception for bad status codes
    ~~~~~~~~~~~~~~~~~~~~~~~~~^^
  File "D:\Repositories\GEN AI\rag\venv\Lib\site-packages\requests\models.py", line 1026, in raise_for_status
    raise HTTPError(http_error_msg, response=self)
requests.exceptions.HTTPError: 400 Client Error: Bad Request for url: https://identitytoolkit.googleapis.com/v1/accounts:signInWithPassword?key=your-firebase-web-api-key
2025-09-23 22:22:47,485 - ERROR - root - firebase_admin_auth - login_with_email_and_password - 110 - Failed to login user: {
  "error": {
    "code": 400,
    "message": "INVALID_LOGIN_CREDENTIALS",
    "errors": [
      {
        "message": "INVALID_LOGIN_CREDENTIALS",
        "domain": "global",
        "reason": "invalid"
      }
    ]
  }
}
Traceback (most recent call last):
  File "D:\Repositories\GEN AI\rag\firebase_admin_auth.py", line 103, in login_with_email_and_password
    response.raise_for_status()  # Raise an exception for bad status codes
    ~~~~~~~~~~~~~~~~~~~~~~~~~^^
  File "D:\Repositories\GEN AI\rag\venv\Lib\site-packages\requests\models.py", line 1026, in raise_for_status
    raise HTTPError(http_error_msg, response=self)
requests.exceptions.HTTPError: 400 Client Error: Bad Request for url: https://identitytoolkit.googleapis.com/v1/accounts:signInWithPassword?key=AIzaSyAUA01g7RrFEdz9tpFpmEiEVB0UV5RP1_w
