2025-09-22 20:55:26,889 - ERROR - root - firebase_admin_auth - initialize_firebase - 19 - Failed to initialize Firebase Admin SDK: [Errno 2] No such file or directory: '/rag-chat-api-key.json'
Traceback (most recent call last):
  File "D:\Repositories\GEN AI\rag\firebase_admin_auth.py", line 13, in initialize_firebase
    cred = credentials.Certificate(config.FIREBASE_SERVICE_ACCOUNT_KEY_PATH)
  File "D:\Repositories\GEN AI\rag\venv\Lib\site-packages\firebase_admin\credentials.py", line 97, in __init__
    with open(cert, encoding='utf-8') as json_file:
         ~~~~^^^^^^^^^^^^^^^^^^^^^^^^
FileNotFoundError: [Errno 2] No such file or directory: '/rag-chat-api-key.json'
2025-09-22 20:56:02,983 - ERROR - root - firebase_admin_auth - initialize_firebase - 19 - Failed to initialize Firebase Admin SDK: [Errno 2] No such file or directory: '/rag-chat-api-key.json'
Traceback (most recent call last):
  File "D:\Repositories\GEN AI\rag\firebase_admin_auth.py", line 13, in initialize_firebase
    cred = credentials.Certificate(config.FIREBASE_SERVICE_ACCOUNT_KEY_PATH)
  File "D:\Repositories\GEN AI\rag\venv\Lib\site-packages\firebase_admin\credentials.py", line 97, in __init__
    with open(cert, encoding='utf-8') as json_file:
         ~~~~^^^^^^^^^^^^^^^^^^^^^^^^
FileNotFoundError: [Errno 2] No such file or directory: '/rag-chat-api-key.json'
2025-09-22 20:56:13,312 - ERROR - root - firebase_admin_auth - initialize_firebase - 19 - Failed to initialize Firebase Admin SDK: [Errno 2] No such file or directory: '/rag-chat-api-key.json'
Traceback (most recent call last):
  File "D:\Repositories\GEN AI\rag\firebase_admin_auth.py", line 13, in initialize_firebase
    cred = credentials.Certificate(config.FIREBASE_SERVICE_ACCOUNT_KEY_PATH)
  File "D:\Repositories\GEN AI\rag\venv\Lib\site-packages\firebase_admin\credentials.py", line 97, in __init__
    with open(cert, encoding='utf-8') as json_file:
         ~~~~^^^^^^^^^^^^^^^^^^^^^^^^
FileNotFoundError: [Errno 2] No such file or directory: '/rag-chat-api-key.json'
2025-09-22 20:56:16,262 - ERROR - root - firebase_admin_auth - initialize_firebase - 19 - Failed to initialize Firebase Admin SDK: name 'firebase_admin' is not defined
Traceback (most recent call last):
  File "D:\Repositories\GEN AI\rag\firebase_admin_auth.py", line 14, in initialize_firebase
    firebase_admin.initialize_app(cred, {
    ^^^^^^^^^^^^^^
NameError: name 'firebase_admin' is not defined
2025-09-22 20:56:53,231 - ERROR - root - firebase_admin_auth - initialize_firebase - 20 - Failed to initialize Firebase Admin SDK: name 'firebase_admin' is not defined
Traceback (most recent call last):
  File "D:\Repositories\GEN AI\rag\firebase_admin_auth.py", line 15, in initialize_firebase
    firebase_admin.initialize_app(cred, {
    ^^^^^^^^^^^^^^
NameError: name 'firebase_admin' is not defined
2025-09-22 20:56:57,542 - ERROR - root - firebase_admin_auth - initialize_firebase - 19 - Failed to initialize Firebase Admin SDK: name 'firebase_admin' is not defined
Traceback (most recent call last):
  File "D:\Repositories\GEN AI\rag\firebase_admin_auth.py", line 14, in initialize_firebase
    firebase_admin.initialize_app(cred, {
    ^^^^^^^^^^^^^^
NameError: name 'firebase_admin' is not defined
2025-09-22 20:57:16,370 - ERROR - root - firebase_admin_auth - initialize_firebase - 20 - Failed to initialize Firebase Admin SDK: name 'firebase_admin' is not defined
Traceback (most recent call last):
  File "D:\Repositories\GEN AI\rag\firebase_admin_auth.py", line 15, in initialize_firebase
    firebase_admin.initialize_app(cred, {
    ^^^^^^^^^^^^^^
NameError: name 'firebase_admin' is not defined
2025-09-22 20:59:01,014 - ERROR - root - firebase_admin_auth - login_with_email_and_password - 108 - Failed to login user: {
  "error": {
    "code": 400,
    "message": "API key not valid. Please pass a valid API key.",
    "errors": [
      {
        "message": "API key not valid. Please pass a valid API key.",
        "domain": "global",
        "reason": "badRequest"
      }
    ],
    "status": "INVALID_ARGUMENT",
    "details": [
      {
        "@type": "type.googleapis.com/google.rpc.ErrorInfo",
        "reason": "API_KEY_INVALID",
        "domain": "googleapis.com",
        "metadata": {
          "service": "identitytoolkit.googleapis.com"
        }
      },
      {
        "@type": "type.googleapis.com/google.rpc.LocalizedMessage",
        "locale": "en-US",
        "message": "API key not valid. Please pass a valid API key."
      }
    ]
  }
}
Traceback (most recent call last):
  File "D:\Repositories\GEN AI\rag\firebase_admin_auth.py", line 101, in login_with_email_and_password
    response.raise_for_status()  # Raise an exception for bad status codes
    ~~~~~~~~~~~~~~~~~~~~~~~~~^^
  File "D:\Repositories\GEN AI\rag\venv\Lib\site-packages\requests\models.py", line 1026, in raise_for_status
    raise HTTPError(http_error_msg, response=self)
requests.exceptions.HTTPError: 400 Client Error: Bad Request for url: https://identitytoolkit.googleapis.com/v1/accounts:signInWithPassword?key=your-firebase-web-api-key
2025-09-23 22:22:47,485 - ERROR - root - firebase_admin_auth - login_with_email_and_password - 110 - Failed to login user: {
  "error": {
    "code": 400,
    "message": "INVALID_LOGIN_CREDENTIALS",
    "errors": [
      {
        "message": "INVALID_LOGIN_CREDENTIALS",
        "domain": "global",
        "reason": "invalid"
      }
    ]
  }
}
Traceback (most recent call last):
  File "D:\Repositories\GEN AI\rag\firebase_admin_auth.py", line 103, in login_with_email_and_password
    response.raise_for_status()  # Raise an exception for bad status codes
    ~~~~~~~~~~~~~~~~~~~~~~~~~^^
  File "D:\Repositories\GEN AI\rag\venv\Lib\site-packages\requests\models.py", line 1026, in raise_for_status
    raise HTTPError(http_error_msg, response=self)
requests.exceptions.HTTPError: 400 Client Error: Bad Request for url: https://identitytoolkit.googleapis.com/v1/accounts:signInWithPassword?key=AIzaSyAUA01g7RrFEdz9tpFpmEiEVB0UV5RP1_w
2025-09-24 01:41:18,882 - ERROR - root - firebase_admin_auth - verify_firebase_token - 34 - Invalid Firebase token: Token expired, 1758658081 < 1758658278
Traceback (most recent call last):
  File "D:\rag\rag_chat_bot\rag-chat-bot\venv\Lib\site-packages\firebase_admin\_token_gen.py", line 396, in verify
    verified_claims = google.oauth2.id_token.verify_token(
        token,
    ...<2 lines>...
        certs_url=self.cert_url,
        clock_skew_in_seconds=clock_skew_seconds)
  File "D:\rag\rag_chat_bot\rag-chat-bot\venv\Lib\site-packages\google\oauth2\id_token.py", line 150, in verify_token
    return jwt.decode(
           ~~~~~~~~~~^
        id_token,
        ^^^^^^^^^
    ...<2 lines>...
        clock_skew_in_seconds=clock_skew_in_seconds,
        ^^^^^^^^^^^^^^^^^^^^^^^^^^^^^^^^^^^^^^^^^^^^
    )
    ^
  File "D:\rag\rag_chat_bot\rag-chat-bot\venv\Lib\site-packages\google\auth\jwt.py", line 302, in decode
    _verify_iat_and_exp(payload, clock_skew_in_seconds)
    ~~~~~~~~~~~~~~~~~~~^^^^^^^^^^^^^^^^^^^^^^^^^^^^^^^^
  File "D:\rag\rag_chat_bot\rag-chat-bot\venv\Lib\site-packages\google\auth\jwt.py", line 228, in _verify_iat_and_exp
    raise exceptions.InvalidValue("Token expired, {} < {}".format(latest, now))
google.auth.exceptions.InvalidValue: Token expired, 1758658081 < 1758658278

During handling of the above exception, another exception occurred:

Traceback (most recent call last):
  File "D:\rag\rag_chat_bot\rag-chat-bot\firebase_admin_auth.py", line 31, in verify_firebase_token
    decoded_token = auth.verify_id_token(token)
  File "D:\rag\rag_chat_bot\rag-chat-bot\venv\Lib\site-packages\firebase_admin\auth.py", line 227, in verify_id_token
    return client.verify_id_token(
           ~~~~~~~~~~~~~~~~~~~~~~^
        id_token, check_revoked=check_revoked, clock_skew_seconds=clock_skew_seconds)
        ^^^^^^^^^^^^^^^^^^^^^^^^^^^^^^^^^^^^^^^^^^^^^^^^^^^^^^^^^^^^^^^^^^^^^^^^^^^^^
  File "D:\rag\rag_chat_bot\rag-chat-bot\venv\Lib\site-packages\firebase_admin\_auth_client.py", line 130, in verify_id_token
    verified_claims = self._token_verifier.verify_id_token(id_token, clock_skew_seconds)
  File "D:\rag\rag_chat_bot\rag-chat-bot\venv\Lib\site-packages\firebase_admin\_token_gen.py", line 293, in verify_id_token
    return self.id_token_verifier.verify(id_token, self.request, clock_skew_seconds)
           ~~~~~~~~~~~~~~~~~~~~~~~~~~~~~^^^^^^^^^^^^^^^^^^^^^^^^^^^^^^^^^^^^^^^^^^^^
  File "D:\rag\rag_chat_bot\rag-chat-bot\venv\Lib\site-packages\firebase_admin\_token_gen.py", line 408, in verify
    raise self._expired_token_error(str(error), cause=error)
firebase_admin._token_gen.ExpiredIdTokenError: Token expired, 1758658081 < 1758658278
2025-09-24 01:41:41,366 - ERROR - root - firebase_admin_auth - verify_firebase_token - 34 - Invalid Firebase token: Token expired, 1758658081 < 1758658301
Traceback (most recent call last):
  File "D:\rag\rag_chat_bot\rag-chat-bot\venv\Lib\site-packages\firebase_admin\_token_gen.py", line 396, in verify
    verified_claims = google.oauth2.id_token.verify_token(
        token,
    ...<2 lines>...
        certs_url=self.cert_url,
        clock_skew_in_seconds=clock_skew_seconds)
  File "D:\rag\rag_chat_bot\rag-chat-bot\venv\Lib\site-packages\google\oauth2\id_token.py", line 150, in verify_token
    return jwt.decode(
           ~~~~~~~~~~^
        id_token,
        ^^^^^^^^^
    ...<2 lines>...
        clock_skew_in_seconds=clock_skew_in_seconds,
        ^^^^^^^^^^^^^^^^^^^^^^^^^^^^^^^^^^^^^^^^^^^^
    )
    ^
  File "D:\rag\rag_chat_bot\rag-chat-bot\venv\Lib\site-packages\google\auth\jwt.py", line 302, in decode
    _verify_iat_and_exp(payload, clock_skew_in_seconds)
    ~~~~~~~~~~~~~~~~~~~^^^^^^^^^^^^^^^^^^^^^^^^^^^^^^^^
  File "D:\rag\rag_chat_bot\rag-chat-bot\venv\Lib\site-packages\google\auth\jwt.py", line 228, in _verify_iat_and_exp
    raise exceptions.InvalidValue("Token expired, {} < {}".format(latest, now))
google.auth.exceptions.InvalidValue: Token expired, 1758658081 < 1758658301

During handling of the above exception, another exception occurred:

Traceback (most recent call last):
  File "D:\rag\rag_chat_bot\rag-chat-bot\firebase_admin_auth.py", line 31, in verify_firebase_token
    decoded_token = auth.verify_id_token(token)
  File "D:\rag\rag_chat_bot\rag-chat-bot\venv\Lib\site-packages\firebase_admin\auth.py", line 227, in verify_id_token
    return client.verify_id_token(
           ~~~~~~~~~~~~~~~~~~~~~~^
        id_token, check_revoked=check_revoked, clock_skew_seconds=clock_skew_seconds)
        ^^^^^^^^^^^^^^^^^^^^^^^^^^^^^^^^^^^^^^^^^^^^^^^^^^^^^^^^^^^^^^^^^^^^^^^^^^^^^
  File "D:\rag\rag_chat_bot\rag-chat-bot\venv\Lib\site-packages\firebase_admin\_auth_client.py", line 130, in verify_id_token
    verified_claims = self._token_verifier.verify_id_token(id_token, clock_skew_seconds)
  File "D:\rag\rag_chat_bot\rag-chat-bot\venv\Lib\site-packages\firebase_admin\_token_gen.py", line 293, in verify_id_token
    return self.id_token_verifier.verify(id_token, self.request, clock_skew_seconds)
           ~~~~~~~~~~~~~~~~~~~~~~~~~~~~~^^^^^^^^^^^^^^^^^^^^^^^^^^^^^^^^^^^^^^^^^^^^
  File "D:\rag\rag_chat_bot\rag-chat-bot\venv\Lib\site-packages\firebase_admin\_token_gen.py", line 408, in verify
    raise self._expired_token_error(str(error), cause=error)
firebase_admin._token_gen.ExpiredIdTokenError: Token expired, 1758658081 < 1758658301
2025-09-24 01:41:43,984 - ERROR - root - firebase_admin_auth - verify_firebase_token - 34 - Invalid Firebase token: Token expired, 1758658081 < 1758658303
Traceback (most recent call last):
  File "D:\rag\rag_chat_bot\rag-chat-bot\venv\Lib\site-packages\firebase_admin\_token_gen.py", line 396, in verify
    verified_claims = google.oauth2.id_token.verify_token(
        token,
    ...<2 lines>...
        certs_url=self.cert_url,
        clock_skew_in_seconds=clock_skew_seconds)
  File "D:\rag\rag_chat_bot\rag-chat-bot\venv\Lib\site-packages\google\oauth2\id_token.py", line 150, in verify_token
    return jwt.decode(
           ~~~~~~~~~~^
        id_token,
        ^^^^^^^^^
    ...<2 lines>...
        clock_skew_in_seconds=clock_skew_in_seconds,
        ^^^^^^^^^^^^^^^^^^^^^^^^^^^^^^^^^^^^^^^^^^^^
    )
    ^
  File "D:\rag\rag_chat_bot\rag-chat-bot\venv\Lib\site-packages\google\auth\jwt.py", line 302, in decode
    _verify_iat_and_exp(payload, clock_skew_in_seconds)
    ~~~~~~~~~~~~~~~~~~~^^^^^^^^^^^^^^^^^^^^^^^^^^^^^^^^
  File "D:\rag\rag_chat_bot\rag-chat-bot\venv\Lib\site-packages\google\auth\jwt.py", line 228, in _verify_iat_and_exp
    raise exceptions.InvalidValue("Token expired, {} < {}".format(latest, now))
google.auth.exceptions.InvalidValue: Token expired, 1758658081 < 1758658303

During handling of the above exception, another exception occurred:

Traceback (most recent call last):
  File "D:\rag\rag_chat_bot\rag-chat-bot\firebase_admin_auth.py", line 31, in verify_firebase_token
    decoded_token = auth.verify_id_token(token)
  File "D:\rag\rag_chat_bot\rag-chat-bot\venv\Lib\site-packages\firebase_admin\auth.py", line 227, in verify_id_token
    return client.verify_id_token(
           ~~~~~~~~~~~~~~~~~~~~~~^
        id_token, check_revoked=check_revoked, clock_skew_seconds=clock_skew_seconds)
        ^^^^^^^^^^^^^^^^^^^^^^^^^^^^^^^^^^^^^^^^^^^^^^^^^^^^^^^^^^^^^^^^^^^^^^^^^^^^^
  File "D:\rag\rag_chat_bot\rag-chat-bot\venv\Lib\site-packages\firebase_admin\_auth_client.py", line 130, in verify_id_token
    verified_claims = self._token_verifier.verify_id_token(id_token, clock_skew_seconds)
  File "D:\rag\rag_chat_bot\rag-chat-bot\venv\Lib\site-packages\firebase_admin\_token_gen.py", line 293, in verify_id_token
    return self.id_token_verifier.verify(id_token, self.request, clock_skew_seconds)
           ~~~~~~~~~~~~~~~~~~~~~~~~~~~~~^^^^^^^^^^^^^^^^^^^^^^^^^^^^^^^^^^^^^^^^^^^^
  File "D:\rag\rag_chat_bot\rag-chat-bot\venv\Lib\site-packages\firebase_admin\_token_gen.py", line 408, in verify
    raise self._expired_token_error(str(error), cause=error)
firebase_admin._token_gen.ExpiredIdTokenError: Token expired, 1758658081 < 1758658303
2025-09-24 01:41:44,207 - ERROR - root - firebase_admin_auth - verify_firebase_token - 34 - Invalid Firebase token: Token expired, 1758658081 < 1758658304
Traceback (most recent call last):
  File "D:\rag\rag_chat_bot\rag-chat-bot\venv\Lib\site-packages\firebase_admin\_token_gen.py", line 396, in verify
    verified_claims = google.oauth2.id_token.verify_token(
        token,
    ...<2 lines>...
        certs_url=self.cert_url,
        clock_skew_in_seconds=clock_skew_seconds)
  File "D:\rag\rag_chat_bot\rag-chat-bot\venv\Lib\site-packages\google\oauth2\id_token.py", line 150, in verify_token
    return jwt.decode(
           ~~~~~~~~~~^
        id_token,
        ^^^^^^^^^
    ...<2 lines>...
        clock_skew_in_seconds=clock_skew_in_seconds,
        ^^^^^^^^^^^^^^^^^^^^^^^^^^^^^^^^^^^^^^^^^^^^
    )
    ^
  File "D:\rag\rag_chat_bot\rag-chat-bot\venv\Lib\site-packages\google\auth\jwt.py", line 302, in decode
    _verify_iat_and_exp(payload, clock_skew_in_seconds)
    ~~~~~~~~~~~~~~~~~~~^^^^^^^^^^^^^^^^^^^^^^^^^^^^^^^^
  File "D:\rag\rag_chat_bot\rag-chat-bot\venv\Lib\site-packages\google\auth\jwt.py", line 228, in _verify_iat_and_exp
    raise exceptions.InvalidValue("Token expired, {} < {}".format(latest, now))
google.auth.exceptions.InvalidValue: Token expired, 1758658081 < 1758658304

During handling of the above exception, another exception occurred:

Traceback (most recent call last):
  File "D:\rag\rag_chat_bot\rag-chat-bot\firebase_admin_auth.py", line 31, in verify_firebase_token
    decoded_token = auth.verify_id_token(token)
  File "D:\rag\rag_chat_bot\rag-chat-bot\venv\Lib\site-packages\firebase_admin\auth.py", line 227, in verify_id_token
    return client.verify_id_token(
           ~~~~~~~~~~~~~~~~~~~~~~^
        id_token, check_revoked=check_revoked, clock_skew_seconds=clock_skew_seconds)
        ^^^^^^^^^^^^^^^^^^^^^^^^^^^^^^^^^^^^^^^^^^^^^^^^^^^^^^^^^^^^^^^^^^^^^^^^^^^^^
  File "D:\rag\rag_chat_bot\rag-chat-bot\venv\Lib\site-packages\firebase_admin\_auth_client.py", line 130, in verify_id_token
    verified_claims = self._token_verifier.verify_id_token(id_token, clock_skew_seconds)
  File "D:\rag\rag_chat_bot\rag-chat-bot\venv\Lib\site-packages\firebase_admin\_token_gen.py", line 293, in verify_id_token
    return self.id_token_verifier.verify(id_token, self.request, clock_skew_seconds)
           ~~~~~~~~~~~~~~~~~~~~~~~~~~~~~^^^^^^^^^^^^^^^^^^^^^^^^^^^^^^^^^^^^^^^^^^^^
  File "D:\rag\rag_chat_bot\rag-chat-bot\venv\Lib\site-packages\firebase_admin\_token_gen.py", line 408, in verify
    raise self._expired_token_error(str(error), cause=error)
firebase_admin._token_gen.ExpiredIdTokenError: Token expired, 1758658081 < 1758658304
2025-09-24 01:41:49,049 - ERROR - root - firebase_admin_auth - verify_firebase_token - 34 - Invalid Firebase token: Token expired, 1758658081 < 1758658309
Traceback (most recent call last):
  File "D:\rag\rag_chat_bot\rag-chat-bot\venv\Lib\site-packages\firebase_admin\_token_gen.py", line 396, in verify
    verified_claims = google.oauth2.id_token.verify_token(
        token,
    ...<2 lines>...
        certs_url=self.cert_url,
        clock_skew_in_seconds=clock_skew_seconds)
  File "D:\rag\rag_chat_bot\rag-chat-bot\venv\Lib\site-packages\google\oauth2\id_token.py", line 150, in verify_token
    return jwt.decode(
           ~~~~~~~~~~^
        id_token,
        ^^^^^^^^^
    ...<2 lines>...
        clock_skew_in_seconds=clock_skew_in_seconds,
        ^^^^^^^^^^^^^^^^^^^^^^^^^^^^^^^^^^^^^^^^^^^^
    )
    ^
  File "D:\rag\rag_chat_bot\rag-chat-bot\venv\Lib\site-packages\google\auth\jwt.py", line 302, in decode
    _verify_iat_and_exp(payload, clock_skew_in_seconds)
    ~~~~~~~~~~~~~~~~~~~^^^^^^^^^^^^^^^^^^^^^^^^^^^^^^^^
  File "D:\rag\rag_chat_bot\rag-chat-bot\venv\Lib\site-packages\google\auth\jwt.py", line 228, in _verify_iat_and_exp
    raise exceptions.InvalidValue("Token expired, {} < {}".format(latest, now))
google.auth.exceptions.InvalidValue: Token expired, 1758658081 < 1758658309

During handling of the above exception, another exception occurred:

Traceback (most recent call last):
  File "D:\rag\rag_chat_bot\rag-chat-bot\firebase_admin_auth.py", line 31, in verify_firebase_token
    decoded_token = auth.verify_id_token(token)
  File "D:\rag\rag_chat_bot\rag-chat-bot\venv\Lib\site-packages\firebase_admin\auth.py", line 227, in verify_id_token
    return client.verify_id_token(
           ~~~~~~~~~~~~~~~~~~~~~~^
        id_token, check_revoked=check_revoked, clock_skew_seconds=clock_skew_seconds)
        ^^^^^^^^^^^^^^^^^^^^^^^^^^^^^^^^^^^^^^^^^^^^^^^^^^^^^^^^^^^^^^^^^^^^^^^^^^^^^
  File "D:\rag\rag_chat_bot\rag-chat-bot\venv\Lib\site-packages\firebase_admin\_auth_client.py", line 130, in verify_id_token
    verified_claims = self._token_verifier.verify_id_token(id_token, clock_skew_seconds)
  File "D:\rag\rag_chat_bot\rag-chat-bot\venv\Lib\site-packages\firebase_admin\_token_gen.py", line 293, in verify_id_token
    return self.id_token_verifier.verify(id_token, self.request, clock_skew_seconds)
           ~~~~~~~~~~~~~~~~~~~~~~~~~~~~~^^^^^^^^^^^^^^^^^^^^^^^^^^^^^^^^^^^^^^^^^^^^
  File "D:\rag\rag_chat_bot\rag-chat-bot\venv\Lib\site-packages\firebase_admin\_token_gen.py", line 408, in verify
    raise self._expired_token_error(str(error), cause=error)
firebase_admin._token_gen.ExpiredIdTokenError: Token expired, 1758658081 < 1758658309
2025-09-24 01:41:49,102 - ERROR - root - firebase_admin_auth - verify_firebase_token - 34 - Invalid Firebase token: Token expired, 1758658081 < 1758658309
Traceback (most recent call last):
  File "D:\rag\rag_chat_bot\rag-chat-bot\venv\Lib\site-packages\firebase_admin\_token_gen.py", line 396, in verify
    verified_claims = google.oauth2.id_token.verify_token(
        token,
    ...<2 lines>...
        certs_url=self.cert_url,
        clock_skew_in_seconds=clock_skew_seconds)
  File "D:\rag\rag_chat_bot\rag-chat-bot\venv\Lib\site-packages\google\oauth2\id_token.py", line 150, in verify_token
    return jwt.decode(
           ~~~~~~~~~~^
        id_token,
        ^^^^^^^^^
    ...<2 lines>...
        clock_skew_in_seconds=clock_skew_in_seconds,
        ^^^^^^^^^^^^^^^^^^^^^^^^^^^^^^^^^^^^^^^^^^^^
    )
    ^
  File "D:\rag\rag_chat_bot\rag-chat-bot\venv\Lib\site-packages\google\auth\jwt.py", line 302, in decode
    _verify_iat_and_exp(payload, clock_skew_in_seconds)
    ~~~~~~~~~~~~~~~~~~~^^^^^^^^^^^^^^^^^^^^^^^^^^^^^^^^
  File "D:\rag\rag_chat_bot\rag-chat-bot\venv\Lib\site-packages\google\auth\jwt.py", line 228, in _verify_iat_and_exp
    raise exceptions.InvalidValue("Token expired, {} < {}".format(latest, now))
google.auth.exceptions.InvalidValue: Token expired, 1758658081 < 1758658309

During handling of the above exception, another exception occurred:

Traceback (most recent call last):
  File "D:\rag\rag_chat_bot\rag-chat-bot\firebase_admin_auth.py", line 31, in verify_firebase_token
    decoded_token = auth.verify_id_token(token)
  File "D:\rag\rag_chat_bot\rag-chat-bot\venv\Lib\site-packages\firebase_admin\auth.py", line 227, in verify_id_token
    return client.verify_id_token(
           ~~~~~~~~~~~~~~~~~~~~~~^
        id_token, check_revoked=check_revoked, clock_skew_seconds=clock_skew_seconds)
        ^^^^^^^^^^^^^^^^^^^^^^^^^^^^^^^^^^^^^^^^^^^^^^^^^^^^^^^^^^^^^^^^^^^^^^^^^^^^^
  File "D:\rag\rag_chat_bot\rag-chat-bot\venv\Lib\site-packages\firebase_admin\_auth_client.py", line 130, in verify_id_token
    verified_claims = self._token_verifier.verify_id_token(id_token, clock_skew_seconds)
  File "D:\rag\rag_chat_bot\rag-chat-bot\venv\Lib\site-packages\firebase_admin\_token_gen.py", line 293, in verify_id_token
    return self.id_token_verifier.verify(id_token, self.request, clock_skew_seconds)
           ~~~~~~~~~~~~~~~~~~~~~~~~~~~~~^^^^^^^^^^^^^^^^^^^^^^^^^^^^^^^^^^^^^^^^^^^^
  File "D:\rag\rag_chat_bot\rag-chat-bot\venv\Lib\site-packages\firebase_admin\_token_gen.py", line 408, in verify
    raise self._expired_token_error(str(error), cause=error)
firebase_admin._token_gen.ExpiredIdTokenError: Token expired, 1758658081 < 1758658309
2025-09-24 01:41:51,683 - ERROR - root - firebase_admin_auth - verify_firebase_token - 34 - Invalid Firebase token: Token expired, 1758658081 < 1758658311
Traceback (most recent call last):
  File "D:\rag\rag_chat_bot\rag-chat-bot\venv\Lib\site-packages\firebase_admin\_token_gen.py", line 396, in verify
    verified_claims = google.oauth2.id_token.verify_token(
        token,
    ...<2 lines>...
        certs_url=self.cert_url,
        clock_skew_in_seconds=clock_skew_seconds)
  File "D:\rag\rag_chat_bot\rag-chat-bot\venv\Lib\site-packages\google\oauth2\id_token.py", line 150, in verify_token
    return jwt.decode(
           ~~~~~~~~~~^
        id_token,
        ^^^^^^^^^
    ...<2 lines>...
        clock_skew_in_seconds=clock_skew_in_seconds,
        ^^^^^^^^^^^^^^^^^^^^^^^^^^^^^^^^^^^^^^^^^^^^
    )
    ^
  File "D:\rag\rag_chat_bot\rag-chat-bot\venv\Lib\site-packages\google\auth\jwt.py", line 302, in decode
    _verify_iat_and_exp(payload, clock_skew_in_seconds)
    ~~~~~~~~~~~~~~~~~~~^^^^^^^^^^^^^^^^^^^^^^^^^^^^^^^^
  File "D:\rag\rag_chat_bot\rag-chat-bot\venv\Lib\site-packages\google\auth\jwt.py", line 228, in _verify_iat_and_exp
    raise exceptions.InvalidValue("Token expired, {} < {}".format(latest, now))
google.auth.exceptions.InvalidValue: Token expired, 1758658081 < 1758658311

During handling of the above exception, another exception occurred:

Traceback (most recent call last):
  File "D:\rag\rag_chat_bot\rag-chat-bot\firebase_admin_auth.py", line 31, in verify_firebase_token
    decoded_token = auth.verify_id_token(token)
  File "D:\rag\rag_chat_bot\rag-chat-bot\venv\Lib\site-packages\firebase_admin\auth.py", line 227, in verify_id_token
    return client.verify_id_token(
           ~~~~~~~~~~~~~~~~~~~~~~^
        id_token, check_revoked=check_revoked, clock_skew_seconds=clock_skew_seconds)
        ^^^^^^^^^^^^^^^^^^^^^^^^^^^^^^^^^^^^^^^^^^^^^^^^^^^^^^^^^^^^^^^^^^^^^^^^^^^^^
  File "D:\rag\rag_chat_bot\rag-chat-bot\venv\Lib\site-packages\firebase_admin\_auth_client.py", line 130, in verify_id_token
    verified_claims = self._token_verifier.verify_id_token(id_token, clock_skew_seconds)
  File "D:\rag\rag_chat_bot\rag-chat-bot\venv\Lib\site-packages\firebase_admin\_token_gen.py", line 293, in verify_id_token
    return self.id_token_verifier.verify(id_token, self.request, clock_skew_seconds)
           ~~~~~~~~~~~~~~~~~~~~~~~~~~~~~^^^^^^^^^^^^^^^^^^^^^^^^^^^^^^^^^^^^^^^^^^^^
  File "D:\rag\rag_chat_bot\rag-chat-bot\venv\Lib\site-packages\firebase_admin\_token_gen.py", line 408, in verify
    raise self._expired_token_error(str(error), cause=error)
firebase_admin._token_gen.ExpiredIdTokenError: Token expired, 1758658081 < 1758658311
2025-09-24 01:41:59,422 - ERROR - root - firebase_admin_auth - verify_firebase_token - 34 - Invalid Firebase token: Token expired, 1758658081 < 1758658319
Traceback (most recent call last):
  File "D:\rag\rag_chat_bot\rag-chat-bot\venv\Lib\site-packages\firebase_admin\_token_gen.py", line 396, in verify
    verified_claims = google.oauth2.id_token.verify_token(
        token,
    ...<2 lines>...
        certs_url=self.cert_url,
        clock_skew_in_seconds=clock_skew_seconds)
  File "D:\rag\rag_chat_bot\rag-chat-bot\venv\Lib\site-packages\google\oauth2\id_token.py", line 150, in verify_token
    return jwt.decode(
           ~~~~~~~~~~^
        id_token,
        ^^^^^^^^^
    ...<2 lines>...
        clock_skew_in_seconds=clock_skew_in_seconds,
        ^^^^^^^^^^^^^^^^^^^^^^^^^^^^^^^^^^^^^^^^^^^^
    )
    ^
  File "D:\rag\rag_chat_bot\rag-chat-bot\venv\Lib\site-packages\google\auth\jwt.py", line 302, in decode
    _verify_iat_and_exp(payload, clock_skew_in_seconds)
    ~~~~~~~~~~~~~~~~~~~^^^^^^^^^^^^^^^^^^^^^^^^^^^^^^^^
  File "D:\rag\rag_chat_bot\rag-chat-bot\venv\Lib\site-packages\google\auth\jwt.py", line 228, in _verify_iat_and_exp
    raise exceptions.InvalidValue("Token expired, {} < {}".format(latest, now))
google.auth.exceptions.InvalidValue: Token expired, 1758658081 < 1758658319

During handling of the above exception, another exception occurred:

Traceback (most recent call last):
  File "D:\rag\rag_chat_bot\rag-chat-bot\firebase_admin_auth.py", line 31, in verify_firebase_token
    decoded_token = auth.verify_id_token(token)
  File "D:\rag\rag_chat_bot\rag-chat-bot\venv\Lib\site-packages\firebase_admin\auth.py", line 227, in verify_id_token
    return client.verify_id_token(
           ~~~~~~~~~~~~~~~~~~~~~~^
        id_token, check_revoked=check_revoked, clock_skew_seconds=clock_skew_seconds)
        ^^^^^^^^^^^^^^^^^^^^^^^^^^^^^^^^^^^^^^^^^^^^^^^^^^^^^^^^^^^^^^^^^^^^^^^^^^^^^
  File "D:\rag\rag_chat_bot\rag-chat-bot\venv\Lib\site-packages\firebase_admin\_auth_client.py", line 130, in verify_id_token
    verified_claims = self._token_verifier.verify_id_token(id_token, clock_skew_seconds)
  File "D:\rag\rag_chat_bot\rag-chat-bot\venv\Lib\site-packages\firebase_admin\_token_gen.py", line 293, in verify_id_token
    return self.id_token_verifier.verify(id_token, self.request, clock_skew_seconds)
           ~~~~~~~~~~~~~~~~~~~~~~~~~~~~~^^^^^^^^^^^^^^^^^^^^^^^^^^^^^^^^^^^^^^^^^^^^
  File "D:\rag\rag_chat_bot\rag-chat-bot\venv\Lib\site-packages\firebase_admin\_token_gen.py", line 408, in verify
    raise self._expired_token_error(str(error), cause=error)
firebase_admin._token_gen.ExpiredIdTokenError: Token expired, 1758658081 < 1758658319
2025-09-24 21:59:02,203 - ERROR - root - firebase_admin_auth - verify_firebase_token - 34 - Invalid Firebase token: Token expired, 1758703905 < 1758731342
Traceback (most recent call last):
  File "D:\Repositories\GEN AI\rag\venv\Lib\site-packages\firebase_admin\_token_gen.py", line 396, in verify
    verified_claims = google.oauth2.id_token.verify_token(
        token,
    ...<2 lines>...
        certs_url=self.cert_url,
        clock_skew_in_seconds=clock_skew_seconds)
  File "D:\Repositories\GEN AI\rag\venv\Lib\site-packages\google\oauth2\id_token.py", line 150, in verify_token
    return jwt.decode(
           ~~~~~~~~~~^
        id_token,
        ^^^^^^^^^
    ...<2 lines>...
        clock_skew_in_seconds=clock_skew_in_seconds,
        ^^^^^^^^^^^^^^^^^^^^^^^^^^^^^^^^^^^^^^^^^^^^
    )
    ^
  File "D:\Repositories\GEN AI\rag\venv\Lib\site-packages\google\auth\jwt.py", line 302, in decode
    _verify_iat_and_exp(payload, clock_skew_in_seconds)
    ~~~~~~~~~~~~~~~~~~~^^^^^^^^^^^^^^^^^^^^^^^^^^^^^^^^
  File "D:\Repositories\GEN AI\rag\venv\Lib\site-packages\google\auth\jwt.py", line 228, in _verify_iat_and_exp
    raise exceptions.InvalidValue("Token expired, {} < {}".format(latest, now))
google.auth.exceptions.InvalidValue: Token expired, 1758703905 < 1758731342

During handling of the above exception, another exception occurred:

Traceback (most recent call last):
  File "D:\Repositories\GEN AI\rag\firebase_admin_auth.py", line 31, in verify_firebase_token
    decoded_token = auth.verify_id_token(token)
  File "D:\Repositories\GEN AI\rag\venv\Lib\site-packages\firebase_admin\auth.py", line 227, in verify_id_token
    return client.verify_id_token(
           ~~~~~~~~~~~~~~~~~~~~~~^
        id_token, check_revoked=check_revoked, clock_skew_seconds=clock_skew_seconds)
        ^^^^^^^^^^^^^^^^^^^^^^^^^^^^^^^^^^^^^^^^^^^^^^^^^^^^^^^^^^^^^^^^^^^^^^^^^^^^^
  File "D:\Repositories\GEN AI\rag\venv\Lib\site-packages\firebase_admin\_auth_client.py", line 130, in verify_id_token
    verified_claims = self._token_verifier.verify_id_token(id_token, clock_skew_seconds)
  File "D:\Repositories\GEN AI\rag\venv\Lib\site-packages\firebase_admin\_token_gen.py", line 293, in verify_id_token
    return self.id_token_verifier.verify(id_token, self.request, clock_skew_seconds)
           ~~~~~~~~~~~~~~~~~~~~~~~~~~~~~^^^^^^^^^^^^^^^^^^^^^^^^^^^^^^^^^^^^^^^^^^^^
  File "D:\Repositories\GEN AI\rag\venv\Lib\site-packages\firebase_admin\_token_gen.py", line 408, in verify
    raise self._expired_token_error(str(error), cause=error)
firebase_admin._token_gen.ExpiredIdTokenError: Token expired, 1758703905 < 1758731342
2025-09-24 21:59:18,707 - ERROR - root - firebase_admin_auth - login_with_email_and_password - 137 - Failed to login user: {
  "error": {
    "code": 400,
    "message": "INVALID_LOGIN_CREDENTIALS",
    "errors": [
      {
        "message": "INVALID_LOGIN_CREDENTIALS",
        "domain": "global",
        "reason": "invalid"
      }
    ]
  }
}
Traceback (most recent call last):
  File "D:\Repositories\GEN AI\rag\firebase_admin_auth.py", line 130, in login_with_email_and_password
    response.raise_for_status()  # Raise an exception for bad status codes
    ~~~~~~~~~~~~~~~~~~~~~~~~~^^
  File "D:\Repositories\GEN AI\rag\venv\Lib\site-packages\requests\models.py", line 1026, in raise_for_status
    raise HTTPError(http_error_msg, response=self)
requests.exceptions.HTTPError: 400 Client Error: Bad Request for url: https://identitytoolkit.googleapis.com/v1/accounts:signInWithPassword?key=AIzaSyAUA01g7RrFEdz9tpFpmEiEVB0UV5RP1_w
2025-09-24 21:59:24,232 - ERROR - root - firebase_admin_auth - login_with_email_and_password - 137 - Failed to login user: {
  "error": {
    "code": 400,
    "message": "INVALID_LOGIN_CREDENTIALS",
    "errors": [
      {
        "message": "INVALID_LOGIN_CREDENTIALS",
        "domain": "global",
        "reason": "invalid"
      }
    ]
  }
}
Traceback (most recent call last):
  File "D:\Repositories\GEN AI\rag\firebase_admin_auth.py", line 130, in login_with_email_and_password
    response.raise_for_status()  # Raise an exception for bad status codes
    ~~~~~~~~~~~~~~~~~~~~~~~~~^^
  File "D:\Repositories\GEN AI\rag\venv\Lib\site-packages\requests\models.py", line 1026, in raise_for_status
    raise HTTPError(http_error_msg, response=self)
requests.exceptions.HTTPError: 400 Client Error: Bad Request for url: https://identitytoolkit.googleapis.com/v1/accounts:signInWithPassword?key=AIzaSyAUA01g7RrFEdz9tpFpmEiEVB0UV5RP1_w
2025-09-24 21:59:47,035 - ERROR - root - firebase_admin_auth - login_with_email_and_password - 137 - Failed to login user: {
  "error": {
    "code": 400,
    "message": "INVALID_LOGIN_CREDENTIALS",
    "errors": [
      {
        "message": "INVALID_LOGIN_CREDENTIALS",
        "domain": "global",
        "reason": "invalid"
      }
    ]
  }
}
Traceback (most recent call last):
  File "D:\Repositories\GEN AI\rag\firebase_admin_auth.py", line 130, in login_with_email_and_password
    response.raise_for_status()  # Raise an exception for bad status codes
    ~~~~~~~~~~~~~~~~~~~~~~~~~^^
  File "D:\Repositories\GEN AI\rag\venv\Lib\site-packages\requests\models.py", line 1026, in raise_for_status
    raise HTTPError(http_error_msg, response=self)
requests.exceptions.HTTPError: 400 Client Error: Bad Request for url: https://identitytoolkit.googleapis.com/v1/accounts:signInWithPassword?key=AIzaSyAUA01g7RrFEdz9tpFpmEiEVB0UV5RP1_w
2025-09-24 21:59:51,137 - ERROR - root - firebase_admin_auth - login_with_email_and_password - 137 - Failed to login user: {
  "error": {
    "code": 400,
    "message": "INVALID_LOGIN_CREDENTIALS",
    "errors": [
      {
        "message": "INVALID_LOGIN_CREDENTIALS",
        "domain": "global",
        "reason": "invalid"
      }
    ]
  }
}
Traceback (most recent call last):
  File "D:\Repositories\GEN AI\rag\firebase_admin_auth.py", line 130, in login_with_email_and_password
    response.raise_for_status()  # Raise an exception for bad status codes
    ~~~~~~~~~~~~~~~~~~~~~~~~~^^
  File "D:\Repositories\GEN AI\rag\venv\Lib\site-packages\requests\models.py", line 1026, in raise_for_status
    raise HTTPError(http_error_msg, response=self)
requests.exceptions.HTTPError: 400 Client Error: Bad Request for url: https://identitytoolkit.googleapis.com/v1/accounts:signInWithPassword?key=AIzaSyAUA01g7RrFEdz9tpFpmEiEVB0UV5RP1_w
2025-09-24 22:00:10,223 - ERROR - root - firebase_admin_auth - verify_firebase_token - 34 - Invalid Firebase token: Token used too early, 1758731410 < 1758731411. Check that your computer's clock is set correctly.
Traceback (most recent call last):
  File "D:\Repositories\GEN AI\rag\venv\Lib\site-packages\firebase_admin\_token_gen.py", line 396, in verify
    verified_claims = google.oauth2.id_token.verify_token(
        token,
    ...<2 lines>...
        certs_url=self.cert_url,
        clock_skew_in_seconds=clock_skew_seconds)
  File "D:\Repositories\GEN AI\rag\venv\Lib\site-packages\google\oauth2\id_token.py", line 150, in verify_token
    return jwt.decode(
           ~~~~~~~~~~^
        id_token,
        ^^^^^^^^^
    ...<2 lines>...
        clock_skew_in_seconds=clock_skew_in_seconds,
        ^^^^^^^^^^^^^^^^^^^^^^^^^^^^^^^^^^^^^^^^^^^^
    )
    ^
  File "D:\Repositories\GEN AI\rag\venv\Lib\site-packages\google\auth\jwt.py", line 302, in decode
    _verify_iat_and_exp(payload, clock_skew_in_seconds)
    ~~~~~~~~~~~~~~~~~~~^^^^^^^^^^^^^^^^^^^^^^^^^^^^^^^^
  File "D:\Repositories\GEN AI\rag\venv\Lib\site-packages\google\auth\jwt.py", line 216, in _verify_iat_and_exp
    raise exceptions.InvalidValue(
    ...<3 lines>...
    )
google.auth.exceptions.InvalidValue: Token used too early, 1758731410 < 1758731411. Check that your computer's clock is set correctly.

During handling of the above exception, another exception occurred:

Traceback (most recent call last):
  File "D:\Repositories\GEN AI\rag\firebase_admin_auth.py", line 31, in verify_firebase_token
    decoded_token = auth.verify_id_token(token)
  File "D:\Repositories\GEN AI\rag\venv\Lib\site-packages\firebase_admin\auth.py", line 227, in verify_id_token
    return client.verify_id_token(
           ~~~~~~~~~~~~~~~~~~~~~~^
        id_token, check_revoked=check_revoked, clock_skew_seconds=clock_skew_seconds)
        ^^^^^^^^^^^^^^^^^^^^^^^^^^^^^^^^^^^^^^^^^^^^^^^^^^^^^^^^^^^^^^^^^^^^^^^^^^^^^
  File "D:\Repositories\GEN AI\rag\venv\Lib\site-packages\firebase_admin\_auth_client.py", line 130, in verify_id_token
    verified_claims = self._token_verifier.verify_id_token(id_token, clock_skew_seconds)
  File "D:\Repositories\GEN AI\rag\venv\Lib\site-packages\firebase_admin\_token_gen.py", line 293, in verify_id_token
    return self.id_token_verifier.verify(id_token, self.request, clock_skew_seconds)
           ~~~~~~~~~~~~~~~~~~~~~~~~~~~~~^^^^^^^^^^^^^^^^^^^^^^^^^^^^^^^^^^^^^^^^^^^^
  File "D:\Repositories\GEN AI\rag\venv\Lib\site-packages\firebase_admin\_token_gen.py", line 409, in verify
    raise self._invalid_token_error(str(error), cause=error)
firebase_admin._auth_utils.InvalidIdTokenError: Token used too early, 1758731410 < 1758731411. Check that your computer's clock is set correctly.
2025-09-24 22:14:36,031 - ERROR - root - firebase_admin_auth - verify_firebase_token - 34 - Invalid Firebase token: Token expired, 1758703905 < 1758732276
Traceback (most recent call last):
  File "D:\Repositories\GEN AI\rag\venv\Lib\site-packages\firebase_admin\_token_gen.py", line 396, in verify
    verified_claims = google.oauth2.id_token.verify_token(
        token,
    ...<2 lines>...
        certs_url=self.cert_url,
        clock_skew_in_seconds=clock_skew_seconds)
  File "D:\Repositories\GEN AI\rag\venv\Lib\site-packages\google\oauth2\id_token.py", line 150, in verify_token
    return jwt.decode(
           ~~~~~~~~~~^
        id_token,
        ^^^^^^^^^
    ...<2 lines>...
        clock_skew_in_seconds=clock_skew_in_seconds,
        ^^^^^^^^^^^^^^^^^^^^^^^^^^^^^^^^^^^^^^^^^^^^
    )
    ^
  File "D:\Repositories\GEN AI\rag\venv\Lib\site-packages\google\auth\jwt.py", line 302, in decode
    _verify_iat_and_exp(payload, clock_skew_in_seconds)
    ~~~~~~~~~~~~~~~~~~~^^^^^^^^^^^^^^^^^^^^^^^^^^^^^^^^
  File "D:\Repositories\GEN AI\rag\venv\Lib\site-packages\google\auth\jwt.py", line 228, in _verify_iat_and_exp
    raise exceptions.InvalidValue("Token expired, {} < {}".format(latest, now))
google.auth.exceptions.InvalidValue: Token expired, 1758703905 < 1758732276

During handling of the above exception, another exception occurred:

Traceback (most recent call last):
  File "D:\Repositories\GEN AI\rag\firebase_admin_auth.py", line 31, in verify_firebase_token
    decoded_token = auth.verify_id_token(token)
  File "D:\Repositories\GEN AI\rag\venv\Lib\site-packages\firebase_admin\auth.py", line 227, in verify_id_token
    return client.verify_id_token(
           ~~~~~~~~~~~~~~~~~~~~~~^
        id_token, check_revoked=check_revoked, clock_skew_seconds=clock_skew_seconds)
        ^^^^^^^^^^^^^^^^^^^^^^^^^^^^^^^^^^^^^^^^^^^^^^^^^^^^^^^^^^^^^^^^^^^^^^^^^^^^^
  File "D:\Repositories\GEN AI\rag\venv\Lib\site-packages\firebase_admin\_auth_client.py", line 130, in verify_id_token
    verified_claims = self._token_verifier.verify_id_token(id_token, clock_skew_seconds)
  File "D:\Repositories\GEN AI\rag\venv\Lib\site-packages\firebase_admin\_token_gen.py", line 293, in verify_id_token
    return self.id_token_verifier.verify(id_token, self.request, clock_skew_seconds)
           ~~~~~~~~~~~~~~~~~~~~~~~~~~~~~^^^^^^^^^^^^^^^^^^^^^^^^^^^^^^^^^^^^^^^^^^^^
  File "D:\Repositories\GEN AI\rag\venv\Lib\site-packages\firebase_admin\_token_gen.py", line 408, in verify
    raise self._expired_token_error(str(error), cause=error)
firebase_admin._token_gen.ExpiredIdTokenError: Token expired, 1758703905 < 1758732276
2025-09-24 22:14:36,039 - ERROR - root - firebase_admin_auth - verify_firebase_token - 34 - Invalid Firebase token: Token expired, 1758703905 < 1758732276
Traceback (most recent call last):
  File "D:\Repositories\GEN AI\rag\venv\Lib\site-packages\firebase_admin\_token_gen.py", line 396, in verify
    verified_claims = google.oauth2.id_token.verify_token(
        token,
    ...<2 lines>...
        certs_url=self.cert_url,
        clock_skew_in_seconds=clock_skew_seconds)
  File "D:\Repositories\GEN AI\rag\venv\Lib\site-packages\google\oauth2\id_token.py", line 150, in verify_token
    return jwt.decode(
           ~~~~~~~~~~^
        id_token,
        ^^^^^^^^^
    ...<2 lines>...
        clock_skew_in_seconds=clock_skew_in_seconds,
        ^^^^^^^^^^^^^^^^^^^^^^^^^^^^^^^^^^^^^^^^^^^^
    )
    ^
  File "D:\Repositories\GEN AI\rag\venv\Lib\site-packages\google\auth\jwt.py", line 302, in decode
    _verify_iat_and_exp(payload, clock_skew_in_seconds)
    ~~~~~~~~~~~~~~~~~~~^^^^^^^^^^^^^^^^^^^^^^^^^^^^^^^^
  File "D:\Repositories\GEN AI\rag\venv\Lib\site-packages\google\auth\jwt.py", line 228, in _verify_iat_and_exp
    raise exceptions.InvalidValue("Token expired, {} < {}".format(latest, now))
google.auth.exceptions.InvalidValue: Token expired, 1758703905 < 1758732276

During handling of the above exception, another exception occurred:

Traceback (most recent call last):
  File "D:\Repositories\GEN AI\rag\firebase_admin_auth.py", line 31, in verify_firebase_token
    decoded_token = auth.verify_id_token(token)
  File "D:\Repositories\GEN AI\rag\venv\Lib\site-packages\firebase_admin\auth.py", line 227, in verify_id_token
    return client.verify_id_token(
           ~~~~~~~~~~~~~~~~~~~~~~^
        id_token, check_revoked=check_revoked, clock_skew_seconds=clock_skew_seconds)
        ^^^^^^^^^^^^^^^^^^^^^^^^^^^^^^^^^^^^^^^^^^^^^^^^^^^^^^^^^^^^^^^^^^^^^^^^^^^^^
  File "D:\Repositories\GEN AI\rag\venv\Lib\site-packages\firebase_admin\_auth_client.py", line 130, in verify_id_token
    verified_claims = self._token_verifier.verify_id_token(id_token, clock_skew_seconds)
  File "D:\Repositories\GEN AI\rag\venv\Lib\site-packages\firebase_admin\_token_gen.py", line 293, in verify_id_token
    return self.id_token_verifier.verify(id_token, self.request, clock_skew_seconds)
           ~~~~~~~~~~~~~~~~~~~~~~~~~~~~~^^^^^^^^^^^^^^^^^^^^^^^^^^^^^^^^^^^^^^^^^^^^
  File "D:\Repositories\GEN AI\rag\venv\Lib\site-packages\firebase_admin\_token_gen.py", line 408, in verify
    raise self._expired_token_error(str(error), cause=error)
firebase_admin._token_gen.ExpiredIdTokenError: Token expired, 1758703905 < 1758732276
2025-09-24 22:15:53,866 - ERROR - root - firebase_admin_auth - login_with_email_and_password - 137 - Failed to login user: {
  "error": {
    "code": 400,
    "message": "INVALID_LOGIN_CREDENTIALS",
    "errors": [
      {
        "message": "INVALID_LOGIN_CREDENTIALS",
        "domain": "global",
        "reason": "invalid"
      }
    ]
  }
}
Traceback (most recent call last):
  File "D:\Repositories\GEN AI\rag\firebase_admin_auth.py", line 130, in login_with_email_and_password
    response.raise_for_status()  # Raise an exception for bad status codes
    ~~~~~~~~~~~~~~~~~~~~~~~~~^^
  File "D:\Repositories\GEN AI\rag\venv\Lib\site-packages\requests\models.py", line 1026, in raise_for_status
    raise HTTPError(http_error_msg, response=self)
requests.exceptions.HTTPError: 400 Client Error: Bad Request for url: https://identitytoolkit.googleapis.com/v1/accounts:signInWithPassword?key=AIzaSyAUA01g7RrFEdz9tpFpmEiEVB0UV5RP1_w
2025-09-24 22:16:41,445 - ERROR - root - firebase_admin_auth - verify_firebase_token - 34 - Invalid Firebase token: Token used too early, 1758732401 < 1758732402. Check that your computer's clock is set correctly.
Traceback (most recent call last):
  File "D:\Repositories\GEN AI\rag\venv\Lib\site-packages\firebase_admin\_token_gen.py", line 396, in verify
    verified_claims = google.oauth2.id_token.verify_token(
        token,
    ...<2 lines>...
        certs_url=self.cert_url,
        clock_skew_in_seconds=clock_skew_seconds)
  File "D:\Repositories\GEN AI\rag\venv\Lib\site-packages\google\oauth2\id_token.py", line 150, in verify_token
    return jwt.decode(
           ~~~~~~~~~~^
        id_token,
        ^^^^^^^^^
    ...<2 lines>...
        clock_skew_in_seconds=clock_skew_in_seconds,
        ^^^^^^^^^^^^^^^^^^^^^^^^^^^^^^^^^^^^^^^^^^^^
    )
    ^
  File "D:\Repositories\GEN AI\rag\venv\Lib\site-packages\google\auth\jwt.py", line 302, in decode
    _verify_iat_and_exp(payload, clock_skew_in_seconds)
    ~~~~~~~~~~~~~~~~~~~^^^^^^^^^^^^^^^^^^^^^^^^^^^^^^^^
  File "D:\Repositories\GEN AI\rag\venv\Lib\site-packages\google\auth\jwt.py", line 216, in _verify_iat_and_exp
    raise exceptions.InvalidValue(
    ...<3 lines>...
    )
google.auth.exceptions.InvalidValue: Token used too early, 1758732401 < 1758732402. Check that your computer's clock is set correctly.

During handling of the above exception, another exception occurred:

Traceback (most recent call last):
  File "D:\Repositories\GEN AI\rag\firebase_admin_auth.py", line 31, in verify_firebase_token
    decoded_token = auth.verify_id_token(token)
  File "D:\Repositories\GEN AI\rag\venv\Lib\site-packages\firebase_admin\auth.py", line 227, in verify_id_token
    return client.verify_id_token(
           ~~~~~~~~~~~~~~~~~~~~~~^
        id_token, check_revoked=check_revoked, clock_skew_seconds=clock_skew_seconds)
        ^^^^^^^^^^^^^^^^^^^^^^^^^^^^^^^^^^^^^^^^^^^^^^^^^^^^^^^^^^^^^^^^^^^^^^^^^^^^^
  File "D:\Repositories\GEN AI\rag\venv\Lib\site-packages\firebase_admin\_auth_client.py", line 130, in verify_id_token
    verified_claims = self._token_verifier.verify_id_token(id_token, clock_skew_seconds)
  File "D:\Repositories\GEN AI\rag\venv\Lib\site-packages\firebase_admin\_token_gen.py", line 293, in verify_id_token
    return self.id_token_verifier.verify(id_token, self.request, clock_skew_seconds)
           ~~~~~~~~~~~~~~~~~~~~~~~~~~~~~^^^^^^^^^^^^^^^^^^^^^^^^^^^^^^^^^^^^^^^^^^^^
  File "D:\Repositories\GEN AI\rag\venv\Lib\site-packages\firebase_admin\_token_gen.py", line 409, in verify
    raise self._invalid_token_error(str(error), cause=error)
firebase_admin._auth_utils.InvalidIdTokenError: Token used too early, 1758732401 < 1758732402. Check that your computer's clock is set correctly.
